Workbook

Sheet Trang tính1
A1: HỘI SINH VIÊN VIỆT NAM TP. HỒ CHÍ MINH BCH TRƯỜNG ĐẠI HỌC SÀI GÒN ____
A2: TỔNG HỢP VÀ PHÂN LOẠI HỒ SƠ TRÌNH HỘI ĐỒNG XÉT DUYỆT DANH HIỆU "SINH VIÊN 5 TỐT" CẤP TRƯỜNG
A3: STT | B3: HỌ VÀ TÊN | C3: MSSV | D3: KHOA | E3: ĐIỂM RÈN LUYỆN | F3: ĐIỂM HỌC TẬP | G3: SĐT | H3: ĐẠT TIÊU CHUẨN | M3: TIÊU BIỂU | N3: PHÂN LOẠI | O3: LINK HỒ SƠ | Q3: GHI CHÚ
H4: ĐẠO ĐỨC | I4: HỌC TẬP | J4: THỂ LỰC | K4: TÌNH NGUYỆN | L4: HỘI NHẬP | O4: BẢNG KHAI | P4: MINH CHỨNG
A6: 1 | B6: Hồ Anh Thư | C6: 3121200023 | D6: GIÁO DỤC CHÍNH TRỊ | E6: =VLOOKUP(C6,'Trang tính3'!$B$10:$H$377,7,0) -> 98 | F6: =VLOOKUP(C6,'Trang tính2'!$B$1:$D$175,3,0) -> 3.33 | H6: - Điển hình Thanh niên tiên tiến làm theo lời Bác khoa Giáo dục Chính trị năm học 2024 – 2025. - Thanh niên tiên tiến trường Đại học Sài Gòn làm theo lời Bác năm học 2024 – 2025. - Bài kỷ yếu trong Tọa đàm Bảo vệ nền tảng tư tưởng của Đảng trong đoàn viên, thanh niên thành phố Hồ Chí Minh chủ đề “Chúng tôi sẵn sàng”. | I6: - KLTN: Sử dụng sơ đồ tư duy trong dạy học môn Giáo dục kinh tế và pháp luật 10; xếp loại: Tốt. | J6: - Đạt danh hiệu “Thanh niên khỏe” trường Đại học Sài Gòn năm 2024. | K6: - Đề xuất bằng khen HSV TP về việc có thành tích xuất sắc trong CDTN MHX 2025 - Chiến dịch Xuân tình nguyện năm 2025 trường Đại học Sài Gòn. - Chiến dịch Mùa hè xanh 2025 trường Đại học Sài Gòn. | L6: - Giấy chứng nhận xuất sắc hoàn thành nhiệm vụ tại khu vực “ASEAN Explorer – Sinh viên Đại học Sài Gòn tự tin hội nhập”. - Chứng chỉ Aptis B1 do Hội đồng Anh cấp ngày 11/6/2025. - Số 304-QĐKT/TĐTN-VP Bằng khen của Thành Đoàn Thành phố Hồ Chí Minh về việc Hoàn thành xuất sắc công tác Đoàn và phong trào thanh niên khu vực trường học thuộc Thành Đoàn năm học 2024 – 2025. | N6: ĐẠT | O6: HỒ ANH THƯ - 3121200023 - GIÁO DỤC CHÍNH TRỊ - BẢNG KHAI THÀNH TÍCH CÁ NHÂN - 2024-2025.pdf | P6: HỒ ANH THƯ - 3121200023 - GIÁO DỤC CHÍNH TRỊ - BẢNG MINH CHỨNG THÀNH TÍCH CÁ NHÂN - 2025.pdf | Q6: 19 SV5T KHOA 8 SV5TTB KHOA
A7: 2 | B7: Trần Anh Thư | C7: 3122200012 | D7: GIÁO DỤC CHÍNH TRỊ | E7: =VLOOKUP(C7,'Trang tính3'!$B$10:$H$377,7,0) -> 95 | F7: =VLOOKUP(C7,'Trang tính2'!$B$1:$D$175,3,0) -> 3.78 | H7: Đạt giấy khen tham gia và có thành tích tốt Phần thi bài luận Hội thi Olympic các môn khoa học Mác - Lênin và tư tưởng Hồ Chí Minh trường Đại học Sài Gòn năm 2025. - Đạt danh hiệu Sao tháng thanh niên SGU “Nghĩ đúng sống đẹp” năm 2025. - Đạt danh hiệu “Thanh niên tiên tiến làm theo lời Bác khoa Giáo dục Chính trị năm học 2024- 2025” | I7: - Chủ nhiệm đề tài: Vấn đề Nhà nước trong tác phẩm “Nhà nước và cách mạng” của V.I.Lênin và sự vận dụng vào việc xây dựng Nhà nước pháp quyền xã hội chủ nghĩa ở Việt Nam hiện nay năm 2024 đạt loại xuất sắc. | J7: - Đạt danh hiệu “Thanh niên khỏe” trường Đại học Sài Gòn năm 2024. | K7: - Tham gia Chương trình “Tiếp sức mùa thi” năm 2025 (04 ngày) - Minh chứng 05 ngày tình nguyện: + 1 ngày : Hưởng ứng chủ nhật xanh + 1 ngày: Tình nguyện viên chương trình “CHO EM ĐẾN TRƯỜNG 2” tại xã Cô Tô, An Giang | L7: - Đạt Chứng chỉ Aptis B2 - Tham gia Nghiệp vụ Sư phạm khoa Giáo dục Chính trị - Đạt giấy chứng nhận tham gia Lớp tập huấn Kỹ năng xác định mục tiêu học tập - Đạt giấy chứng nhận Workshop AI thực chiến: Làm chủ công nghệ, bức phá thành công - Đạt giấy chứng nhận hoàn thành Chương trình “Phổ Cập AI” - Đạt giấy chứng nhận đã hoàn thành khóa học “Thanh niên tình nguyện hỗ trợ chính quyền địa phương hai cấp” - Tham gia cuộc thi “Sắc màu Đông Nam Á” - Đạt giấy chứng nhận Ngày hội sinh viên với ngoại ngữ năm 2025 chủ đề “GenZith HORIZON”. | N7: ĐẠT | O7: TRẦN ANH THƯ - 3122200012 - GIÁO DỤC CHÍNH TRỊ - BẢNG KHAI THÀNH TÍCH CÁ NHÂN.docx | P7: TRẦN ANH THƯ - 3122200012 - GIÁO DỤC CHÍNH TRỊ - MINH CHỨNG THÀNH TÍCH CÁ NHÂN.pdf
A8: 3 | B8: Võ Cẩm Giang | C8: 3122200003 | D8: GIÁO DỤC CHÍNH TRỊ | E8: =VLOOKUP(C8,'Trang tính3'!$B$10:$H$377,7,0) -> 93 | F8: =VLOOKUP(C8,'Trang tính2'!$B$1:$D$175,3,0) -> 3.90 | H8: - Đạt danh hiệu điển hình Thanh niên tiên tiến làm theo lời Bác Khoa Giáo dục Chính trị năm học 2024 – 2025. - Quyết định số 06 QĐCN/ĐTN-VP ngày 17/04/2025 của Ban Thường Vụ Đoàn Trường – Ban Thư Ký Hội sinh viên trường Đại học Sài Gòn danh hiệu “Sao tháng thanh niên SGU” năm học 2024 – 2025. - Tháng 5/2025: Giải Khuyến khích Hội thi “Học tập và làm theo tư tưởng, đạo đức, phong cách Hồ Chí Minh” – Chủ đề: “Người là niềm tin tất thắng”. - Giấy khen của Đảng ủy Phường 2 “đã tích cực tham gia đợt hoạt động kỷ niệm 135 năm ngày sinh Chủ tịch Hồ Chí Minh (19/05/1890 – 19/05/2025)”. | I8: - Tháng 5/2025: Giấy chứng nhận hoàn thành đề tài NCKH cấp Trường: “Nâng cao ý thức đạo đức của sinh viên Trường Đại học Sài Gòn trong giao tiếp mạng xã hội hiện nay” – Xếp loại Tốt | J8: - Đạt danh hiệu “Thanh niên khỏe” trường Đại học Sài Gòn năm 2024. | K8: Tháng 10/2024: Tham gia Workshop “Tôi chọn sống xanh” (1 lượt) Tháng 11/2024: Tham gia hiến máu tình nguyện (1 lượt) Tháng 05/2025: Tham gia hiến máu tình nguyện (1 lượt) Tháng 7/2025: Tham gia hoạt động “Vì đàn em thân yêu” lần thứ 15 (1 lượt) Tháng 9/2025: Tham gia hoạt động “Trung thu cho em” tại địa bàn Phường Phú Nhuận (1 lượt) Tháng 10/2025: Tham gia gây quỹ “Trung thu yêu thương – Sum vầy” (1 lượt) | L8: Aptis Esol B2 Tháng 5/2025: Giấy chứng nhận hoàn thành phổ cập AI Tháng 11/2024: Tham gia nghiệp vụ sư phạm cấp trường 2023 – 2024. Tháng 11/2024: Tham gia hội thi Nghiệp vụ Sư phạm khoa Giáo dục Chính trị năm 2024. - Tháng 5/2025: Tham gia trực tuyến cuộc thi “Sắc màu Đông Nam Á- Chặng 2: Bản lĩnh ASEAN” | N8: ĐẠT | O8: VÕ CẨM GIANG - 3122200003- KHOA GIÁO DỤC CHÍNH TRỊ - BẢNG KHAI THÀNH TÍCH CÁ NHÂN - 2024-2025.docx | P8: VÕ CẨM GIANG - 3122200003- KHOA GIÁO DỤC CHÍNH TRỊ - MINH CHỨNG THÀNH TÍCH CÁ NHÂN - 2025 (1).docx
A9: 4 | B9: Võ Thanh Quyền | C9: 3122200009 | D9: GIÁO DỤC CHÍNH TRỊ | E9: =VLOOKUP(C9,'Trang tính3'!$B$10:$H$377,7,0) -> 97 | F9: =VLOOKUP(C9,'Trang tính2'!$B$1:$D$175,3,0) -> 3.62 | H9: Đạt danh hiệu Sao tháng thanh niên SGU “Nghĩ đúng sống đẹp” năm 2025. Đạt danh hiệu “Thanh niên tiên tiến làm theo lời Bác khoa Giáo dục Chính trị năm học 2024 – 2025” | I9: - Đạt giải nhì “Hội thi tìm hiểu pháp luật trực tuyến năm 2025” do UBND Phường 2, Quận 5 tổ chức. | J9: - Đạt giấy chứng nhận đã tham gia Giải Việt dã Học sinh, Sinh viên TP. Hồ Chí Minh mở rộng năm 2025 Cúp “Chị Ngã Em Nâng” | K9: - Tham gia chương trình “Tiếp sức mùa thi” năm 2025 + Tham gia Ngày tình nguyện “Tôi chọn sống xanh” : 1 lượt + Tham gia hoạt động “Trồng cây gieo yêu thương” : 1 lượt + Tình nguyện viên đã tham gia Lễ đón, Lễ tiễn Tổng Bí thư, Chủ tịch Bước Cộng hòa Dân chủ Nhân dân Lào thăm Thành phố Hồ Chí Minh: 2 lượt + Tham gia lễ ra quân Tuổi trẻ Thành phố Bác xung kích xây dựng văn minh, mỹ quan đô thị: 1 lượt | L9: - Chứng chỉ Aptis B1 - Giấy chứng nhận đã hoàn thành khóa học “ Thanh niên tình nguyện hỗ trợ chính quyền địa phương hai cấp” - Giấy chứng nhận đã hoàn thành Khóa học Ứng dụng AI cho Thanh niên Việt Nam - Giấy chứng nhận đã tham gia chương trình Trang bị Kỹ năng nghề nghiệp - Giấy khen “Đã có đóng góp tích cực trong công tác Đoàn và phong trào thanh niên Trường Đại học Sài Gòn năm học 2024 – 2025” - Tham gia hành trình 5 tốt “Hội nhập cùng ASEAN” - Tháng 5/2025: Tham gia cuộc thi “Sắc màu Đông Nam Á” | N9: ĐẠT | O9: VÕ THANH QUYẾN - 3122200009 - GIÁO DỤC CHÍNH TRỊ - BẢNG KHAI THÀNH TÍCH CÁ NHÂN.docx | P9: VÕ THANH QUYẾN - 3122200009 - GIÁO DỤC CHÍNH TRỊ - BẢNG KHAI MINH CHỨNG (2).docx
A10: 5 | B10: Lê Thị Thùy Linh | C10: 3121200013 | D10: GIÁO DỤC CHÍNH TRỊ | E10: =VLOOKUP(C10,'Trang tính3'!$B$10:$H$377,7,0) -> 100 | F10: =VLOOKUP(C10,'Trang tính2'!$B$1:$D$175,3,0) -> 3.90 | H10: Đạt danh hiệu Thanh niên tiên tiến Trường Đại học Sài Gòn làm theo lời Bác năm học 2024 - 2025 theo Giấy chứng nhận số 43-GCN/ĐU ngày 12/5/2025 của Đảng ủy trường. Có thành tích tốt trong Phần thi bài luận Hội thi Olympic các môn khoa học Mác - Lênin và tư tưởng Hồ Chí Minh Trường Đại học Sài Gòn năm 2025 theo Giấy khen số 11-QĐKT/ĐTN-VP. Đánh giá chất lượng đoàn viên cuối năm đạt Hoàn thành xuất sắc nhiệm vụ. | I10: Hoàn thành khóa luận tốt nghiệp đạt loại 9.7 điểm với tên đề tài Nâng cao hiệu quả học tập phong cách tư duy Hồ ChíMinh trong sinh viên trường Đại học Sài Gòn hiện nay. | J10: Đạt danh hiệu Thanh niên khỏe trường Đại học Sài Gòn năm 2024 theo Giấy chứng nhận số 02 - QĐGCN/HSV ngày 05/10/2024. | K10: Đạt thành tích xuất sắc trong Chiến dịch Xuân Tình nguyện trường Đại học Sài Gòn lần thứ 17 năm 2025 theo Giấy khen số 02/QĐ-BTK ngày 25/01/2025. Tham gia và hoàn thành Chiến dịch Xuân tình nguyện Trường Đại học Sài Gòn lần thứ 17 năm 2025 theo Giấy chứng nhận số 02-QĐGCN/HSV. Tham gia chương trình Hoạt động trồng cây - gieo yêu thương tương ứng 01 ngày tình nguyện. Tham gia hoạt động Xuân tình nguyện Cụm hoạt động số 01 tương ứng 01 ngày tình nguyện. Tham gia Ngày Chủ nhật Xanh lần thứ 156 năm 2025 tương ứng 01 ngày tình nguyện. Tham gia hoạt động tình nguyện Theo dấu chân hạnh phúc năm học 2024 - 2025 tương ứng 01 ngày tình nguyện. Tham gia chương trình Ngày tình nguyện Tôi chọn Sống Xanh năm học 2024 - 2025 tương ứng 01 ngày tình nguyện. | L10: Đạt chứng chỉ tiếng Anh trình độ B1 theo khung tham chiếu châu Âu. Tham gia Chương trình giao lưu và tặng quà cho sinh viên Lào tại Ký túc xá Sinh viên Lào Thành phố Hồ Chí Minh ngày 01/02/2025 theo Giấy chứng nhận số 03 - QĐGCN/HSV. Xuất sắc hoàn thành nhiệm vụ tại khu vực ASEAN Explorer - Sinh viên Đại học Sài Gòn tự tin hội nhập năm 2024 theo Giấy chứng nhận số 01 - QĐGCN/HSV ngày 05/10/2024. Tham gia Buổi chuyên đề Ứng dụng kỹ năng số cho sinh viên trường Đại học Sài Gòn năm 2024 theo Giấy chứng nhận số 03 - QĐGCN/HSV ngày 29/11/2024. Tham gia Tập huấn chuyên đề An toàn giao thông và kỹ năng phòng tránh va chạm trong các hoạt động tình nguyện ngày 04/01/2025 theo Giấy chứng nhận số 01 - QĐGCN/HSV. Có chứng chỉ tin học quốc tế MOS. | M10: Đề xuất tiêu biểu | N10: ĐẠT | P10: 1. Lê Thị Thuỳ Linh
A11: 6 | B11: Nguyễn Thị Phương Khiêm | C11: 3122200005 | D11: GIÁO DỤC CHÍNH TRỊ | E11: =VLOOKUP(C11,'Trang tính3'!$B$10:$H$377,7,0) -> 98.5 | F11: =VLOOKUP(C11,'Trang tính2'!$B$1:$D$175,3,0) -> 3.71 | H11: Đánh giá chất lượng Đoàn viên cuối năm đạt Hoàn thành xuất sắc nhiệm vụ. Đạt danh hiệu "Thanh niên tiên tiến Trường Đại học Sài Gòn làm theo lời Bác" năm học 2024 - 2025 theo Giấy chứng nhận số 47-GCN/ĐU ngày 12/05/2025. | I11: Đạt danh hiệu Sinh viên 5 tốt cấp trường năm học 2024 - 2025. Đề tài nghiên cứu khoa học sinh viên được hội đồng khoa học cấp Trường nghiệm thu đánh giá loại tốt với tên đề tài:Văn hoá ứng xử của sinh viên Trường Đại học Sài Gòn - Thực | J11: Đạt danh hiệu "Thanh niên khỏe" trường Đại học Sài Gòn năm 2024 theo Giấy chứng nhận số 02-QĐGCN/HSV ngày 05/10/2024. Đạt giải Ba môn Cầu lông nữ tại Hội thao năm 2025 chào mừng Đại hội đại biểu Hội Sinh viên Việt Nam trường Đại học Sài Gòn lần thứ IX theo Giấy khen số 42/QĐ-BTK ngày 13/07/2025. | K11: Nhận Bằng khen của Ban Chấp hành Hội Sinh viên Thành phố Hồ Chí Minh vì đã có thành tích xuất sắc trong Chương trình "Tiếp sức mùa thi" năm 2025. Tham gia và hoàn thành Chiến dịch Mùa hè xanh 2024 và Chương trình Tiếp sức mùa thi 2025. Thực hiện hiến máu tình nguyện 03 lần vào các tháng 11/2024, 03/2025 và 07/2025. Tham gia 09 ngày tình nguyện trong chương trình Tiếp sức mùa thi 2025. Tham gia các hoạt động tình nguyện: "Theo dấu chân hạnh phúc", "Tôi chọn sống xanh", "Hoạt động trồng cây - gieo yêu thương", "Xuân Tình nguyện Cụm hoạt động số 1" và Ngày Chủ nhật Xanh lần thứ 156. | L11: Đạt chứng chỉ ngoại ngữ Aptis trình độ B2 theo khung tham chiếu châu Âu. Tham gia Ngày hội sinh viên với ngoại ngữ năm 2025 chủ đề "GenZith HORIZON". Tham gia Chương trình giao lưu và tặng quà cho sinh viên Lào tại Ký túc xá Sinh viên Lào Thành phố Hồ Chí Minh ngày 01/02/2025. Xuất sắc hoàn thành nhiệm vụ tại khu vực "ASEAN Explorer - Sinh viên Đại học Sài Gòn tự tin hội nhập" năm 2024. Nhận Giấy khen của Ban Chấp hành Đoàn trường vì có đóng góp tích cực trong công tác Đoàn và phong trào thanh niên năm học 2023 - 2024. Hoàn thành các khóa tập huấn kỹ năng: Xác định mục tiêu học tập, Workshop AI thực chiến, Ứng dụng kỹ năng số và tập huấn An toàn giao thông. Có chứng chỉ ứng dụng Công nghệ thông tin cơ bản và ứng dụng Công nghệ thông tin trong dạy học. | M11: Đề xuất tiêu biểu | N11: ĐẠT | P11: 2. NGUYỄN THỊ PHƯƠNG KHIÊM
A12: 7 | B12: Bùi Cao Ái Trân | C12: 3123430196 | D12: LUẬT | E12: =VLOOKUP(C12,'Trang tính3'!$B$10:$H$377,7,0) -> 100 | F12: =VLOOKUP(C12,'Trang tính2'!$B$1:$D$175,3,0) -> 3.1 | I12: Không đạt phần NCKH | N12: KHÔNG ĐẠT | O12: BÙI CAO ÁI TRÂN - 3123430196– KHOA LUẬT – BẢNG KHAI THÀNH TÍCH(1) (2).docx | P12: BÙI CAO ÁI TRÂN – MSSV 3123430196– KHOA LUẬT – MINH CHỨNG THÀNH TÍCH(2) (1)-trang.docx | Q12: 31 SV5T KHOA 7 SV5TTB KHOA
A13: 8 | B13: Bùi Thanh Xuân | C13: 3123430222 | D13: LUẬT | E13: =VLOOKUP(C13,'Trang tính3'!$B$10:$H$377,7,0) -> 89 | F13: =VLOOKUP(C13,'Trang tính2'!$B$1:$D$175,3,0) -> 3.79 | H13: - Là thành viên tham gia và đạt Giải ba Hội thi vẽ, thiết kế sản phẩm tuyên truyền chào mừng kỷ niệm 50 năm ngày giải phóng miền Nam,thống nhất đất nước 30/4/1975-30/4/2025 chủ đề “Trường Thọ trong tôi- Rạng ngời trang sử Việt” ( quyết định 119/QĐ-UBND ngày 20 tháng 3 năm 2025) | I13: -Đã tham gia viết bài tại DIỄN ĐÀN KHOA HỌC TRẺ “LUẬT HỌC MÙA XUÂN”- VNU-UL SPRING LAW FORUM Hội thảo chuyên để số 1 chủ đề "Xây dựng tổ chức bộ máy nhà nước tinh gọn, hoạt động hiệu lực, hiệu quả ở Việt Nam trong bối cảnh phát triển mới và những vẫn đề pháp lý đặt ra do Trường Đại học Luật, ĐHQGHN tổ chức từ ngày 11/04 đến ngày 12/04/2025 tại Hà Nội và được đưa vào kỷ yếu hội thảo. | J13: Đạt danh hiệu “ Thanh Niên Khỏe” 2025: GO! (KHXH&NV) | K13: - Đã có thành tích xuất sắc trong chiến dịch ra quân Chủ nhật xanh lần thứ 158 – 2025 -Tham gia quyên góp chương trình tình nguyện ngắn ngày “Dâng hương, dâng hoa Khu truyền thống cách mạng cuộc Tổng tiến công và nổi dậy xuân Mậu Thân 1968”. Đạt danh hiệu “ĐẠI SỨ ÁO XANH TÌNH NGUYỆN 2024” nhận ngày 24 tháng 12 năm 2024 từ BCH đoàn phường. | L13: Bằng APTIS ESOL GENERAL loại B1 của Hội Đồng Anh Việt Nam cấp ngày 28.08.2025 -Tham gia Tọa đàm “ Hành trang hành nghề Luật sư – Những kỹ năng không thể thiếu” ngày 27 tháng 3 năm 2025 -Tham gia vòng sơ loại Cuộc Thi Law Changllange” năm 2025 ngày 8 tháng 3 năm 2025 - Tham gia “ Cuộc thi Hòa giải thương mại Việt Nam 2025”- VIETNAM MEDIATION MOOT – VMED 2025 -Tập thể Chi đoàn Thanh niên khu phố 22: Đã có thành tích xuất sắc trong công tác đoàn và phong trào thanh thiếu nhi năm 2024 (quyết định số 103-QĐKT/ĐTN ngày 23 tháng 1 năm 2025 BTV đoàn phường) - Đạt thành tích xuất sắc trong hoạt động Hè phường Thủ Đức 2025 - Tham gia Chuyên đề “TUYÊN TRUYỀN PHÒNG, NGỪA TỘI PHẠM LỪA ĐẢO QUA MẠNG XÃ HỘI TRONG BỐI CẢNH CHUYỂN ĐỔI SỐ” | N13: ĐẠT | O13: BÙI THANH XUÂN -3123430222-Khoa Luật- BẢNG KHAI THÀNH TÍCH (1).docx | P13: BÙI THANH XUÂN - 3123430222 - Khoa Luật -MINH CHỨNG THÀNH TÍCH (1).docx
A14: 9 | B14: Đỗ Lê Kim Yến | C14: 3123430228 | D14: LUẬT | E14: =VLOOKUP(C14,'Trang tính3'!$B$10:$H$377,7,0) -> 90.5 | F14: =VLOOKUP(C14,'Trang tính2'!$B$1:$D$175,3,0) -> 3.66 | I14: Không đạt phần "tiêu chuẩn khác" | N14: KHÔNG ĐẠT | O14: ĐỖ LÊ KIM YẾN - 3123430228 - KHOA LUẬT - BẢNG KHAI THÀNH TÍCH | P14: ĐỖ LÊ KIM YẾN - 3123430228 - KHOA LUẬT - MINH CHỨNG THÀNH TÍCH
A15: 10 | B15: Mai Nguyễn Trà My | C15: 3122430104 | D15: LUẬT | E15: =VLOOKUP(C15,'Trang tính3'!$B$10:$H$377,7,0) -> 100 | F15: =VLOOKUP(C15,'Trang tính2'!$B$1:$D$175,3,0) -> 3.76 | H15: Thành viên đội Luật 2 tham gia Hội thi olympic các môn khoa học Mác - Lênin và Tư tưởng Hồ Chí Minh Đoàn viên Hoàn thành xuất sắc nhiệm vụ Điển hình Thanh niên tiên tiến khoa Luật làm theo lời Bác năm học 2024 – 2025 Thanh niên tiên tiến trường Đại học Sài Gòn làm theo lời Bác năm học 2024 – 2025 Giấy chứng nhận danh hiệu “Sao Tháng Thanh niên SGU Nghĩ đúng – Sống đẹp” năm 2025. | I15: Thành viên CLB Hạt giống khoa Luật | J15: Tham gia Giải Việt dã Học sinh, Sinh viên TP. Hồ Chí Minh mở rộng năm 2025 Cúp “Chị Ngã Em Nâng” | K15: Chiến sĩ đội hình Xuân Chiến sĩ chiến dịch Xuân Tình Nguyện năm 2025 Chiến sĩ đội hình Pháp luật chiến dịch Mùa Hè Xanh năm 2025. Tham gia đội hình văn nghệ Chào mừng kỷ niệm 50 năm ngày Giải phóng miền Nam, thống nhất Đất nước. | L15: Chứng chỉ APTIS ESOL – Cefr Level B2 cấp bởi British Council vào tháng 02/2025. Giấy khen “Đã có thành tích xuất sắc trong Công tác Hội và Phong trào sinh viên trường Đại học Sài Gòn năm học 2024 – 2025” Giấy khen danh hiệu “Cán bộ Đoàn tiêu biểu” năm học 2024 – 2025 Tham gia Hội thi “Tiến lên cùng Chi hội” lần thứ II năm học 2024 – 2025 Chương trình “Âm vang khoa Luật” năm 2024 Tham gia Sân chơi Hội nhập “Ring The Golden Bell” năm 2025 | N15: ĐẠT | O15: MAI NGUYỄN TRÀ MY - 3122430104 - KHOA LUẬT - BẢNG KHAI THÀNH TÍCH.docx | P15: MAI NGUYỄN TRÀ MY - 3122430104 - KHOA LUẬT - MINH CHỨNG THÀNH TÍCH.docx
A16: 11 | B16: Nguyễn Đắc Triết | C16: 3122430202 | D16: LUẬT | E16: =VLOOKUP(C16,'Trang tính3'!$B$10:$H$377,7,0) -> 100 | F16: =VLOOKUP(C16,'Trang tính2'!$B$1:$D$175,3,0) -> 3.26 | H16: Bằng khen số: 65/QĐ-UBH ngày 29 tháng 11 năm 2024 của Ủy ban Hội Liên hiệp Thanh niên Việt Nam Thành phố Hồ Chí Minh khen tặng vì đã có thành tích xuất sắc trong hoạt động tình nguyện, công tác xã hội trên địa bàn Thành phố năm 2024; Được khen thưởng theo Quyết định số 35-QD/ĐU ngày 01/10/2025 của Đảng ủy trường Đại học Sài Gòn về khen thưởng các tập thể, cá nhân thực hiện tốt công tác Dân vận năm 2025; Đạt giải Nhất Hội thi trực tuyến “Sài Gòn – Thành phố tôi yêu” do Chi bộ Sinh viên 1 trường Đại học Sài Gòn tổ chức; Đạt Danh hiệu “Đảng viên trẻ Tiêu biểu năm 2024” Chi bộ Sinh viên 1. | I16: - Là Tác giả của đề tài: Hoãn chấp hành hình phạt tù theo quy định của pháp luật Hình sự Việt Nam (NCKH); Đạt giải Nhì Cuộc thi “Thinklaw – Tư duy pháp lý Nghề luật” – Lần 1/2025. Do trường Đại học Nguyễn Tất Thành tổ chức. | J16: Đạt Danh hiệu “Thanh niên khỏe” trường Đại học Sài Gòn năm học 2024 – 2025. (18/8/2025); Đạt Danh hiệu “Thanh niên khỏe” trường Đại học Sài Gòn năm 2024. (05/10/2024); Đạt giải Ba môn Cầu lông (Đơn nam) trong hoạt động Hội thao các Chi bộ Sinh viên. | K16: Giấy khen Số: 02/QĐ-BTK ngày 25 tháng 01 năm 2025 của BCH HSV trường Đại học Sài Gòn về việc Đã có thành tích xuất sắc trong Chiến dịch Xuân Tình nguyện trường Đại học Sài Gòn lần thứ 17 năm 2025; Tham gia và được nhận giấy chứng nhận và giấy khen của Hội Sinh viên trường trong dịp Xuân tình nguyện năm 2025; Tham gia và được nhận giấy chứng nhận trong dịp Mùa hè xanh năm 2024; Tham gia và được giấy chứng nhận của trung tâm hỗ trợ học sinh, sinh viên trong dịp tiếp sức mùa thi năm 2025; Tham gia và được giấy chứng nhận của Ban thư ký Hội Sinh viên trường trong “Chương trình giao lưu và tặng quà cho sinh viên Ký túc xá sinh viên Lào”; Tham gia và được nhận giấy chứng nhận của Ban thư ký Hội Sinh viên trường trong chương trình đồng diễn “Hòa bình đẹp lắm” nhân dịp 30/4/2025; Được nhận giấy chứng nhận của Hội Liên hiệp thanh niên TP. HCM vì có thành tích xuất sắc trong công tác tình nguyện; Tham gia và đạt giấy chứng nhận của BCH Hội sinh viên Thành phố trong chương trình Hòa ca “Đất nước trọn niềm vui”. | L16: Đạt B1 Aptis; Tham gia và đạt giấy chứng nhận của của Ban thư ký Hội Sinh viên trường trong chuyên đề “An toàn giao thông”; Hoàn thành lớp học và được cấp chứng chỉ sử dụng Công nghệ thông tin cơ bản do trường Đại học Sài Gòn tổ chức; Tham gia và đạt giấy chứng nhận của của Ban thư ký Hội Sinh viên trường trong chuyên đề “Ứng dụng kỹ năng số”; Bằng khen số: 33/QĐ-TĐKT ngày 10 tháng 10 năm 2025 của Ban chấp hành Hội Sinh viên Việt Nam Thành phố Hồ Chí Minh khen tặng vì đã có thành tích xuất sắc trong công tác Hội và phong trào sinh viên Thành phố năm học 2024 – 2025; Tham gia và đạt giấy chứng nhận của Ban thư ký Hội Sinh viên trường trong khu vực ASEAN – tự tin Hội nhập trong khuôn khổ ngày hội TSV năm 2024 (05/10/2024). | N16: ĐẠT | O16: NGUYỄN ĐẮC TRIẾT - 3122430202 - LUẬT - BẢNG KHAI THÀNH TÍCH | P16: NGUYỄN ĐẮC TRIẾT - 3122430202 - LUẬT - MINH CHỨNG THÀNH TÍCH.docx
A17: 12 | B17: Nguyễn Hữu Thiện Nhiên | C17: 3123430131 | D17: LUẬT | E17: =VLOOKUP(C17,'Trang tính3'!$B$10:$H$377,7,0) -> 100 | F17: =VLOOKUP(C17,'Trang tính2'!$B$1:$D$175,3,0) -> 3.91 | H17: Là thanh niên tiên tiến làm theo lời Bác cấp khoa (được tuyên dương vào ngày 15/5/2025) Quyết định số 06-QĐCN/ĐTN-VP của Ban Thường vụ Đoàn trường và Ban Thư Ký Hội sinh viên trường ngày 17/04/2025 về việc trao giấy chứng nhận Đạt danh hiệu Sao Tháng thanh niên SGU – nghĩ đúng sống đẹp 2025. | I17: Là chủ nhiệm đề tài “Pháp luật về quyền tự do ngôn luận trên không gian mạng” năm 2024 – 2025; Đạt giải Nhất cuộc thi học thuật Law’s challenge 2024 do Đoàn Khoa Luật tổ chức; Đạt giải nhì Ring the golden bell 2025 do Liên chi Hội sinh viên Khoa Luật tố chức; Đạt giải Nhì Cuộc thi “Thinklaw – Tư duy pháp lý Nghề luật” – Lần 1/2025. Do trường Đại học Nguyễn Tất Thành tổ chức. Là thành viên tham gia tham gia tích cực trong CLB Thực hành pháp luật khoa Luật trường Đại học Sài Gòn. | J17: Đạt Danh hiệu “Thanh niên khỏe” trường Đại học Sài Gòn năm học 2024 – 2025 | K17: Quyết định số 14-QĐKT/ĐTN-VP của Ban Chấp Hành Đoàn Trường Đại học Sài Gòn ngày 08/08/2025 về việc trao giấy khen vì đã đóng góp tích cực trong Chiến dịch Mùa hè xanh trường Đại học Sài Gòn lần thứ 32 năm 2025; Quyết định số 02/QĐ-BTK của Ban Chấp Hành Hội sinh viên Trường Đại học Sài Gòn ngày 25/01/2025 về việc trao giấy khen vì đã đóng góp tích cực trong Chiến dịch Xuân tình nguyện trường Đại học Sài Gòn lần thứ 17 năm 2025. Tham gia và được cấp giấy chứng nhận hoàn thành chiến dịch Xuân tình nguyện 2025; Tham gia và được cấp giấy chứng nhận hoàn thành chiến dịch Mùa hè xanh 2025; Tham gia và được cấp giấy chứng nhận hoàn thành chương trình tình nguyện Tiếp sức mùa thi 2025; Tham gia và được cấp giấy chứng nhận hoàn thành Tiếp sức đến trường 2025 + 01 ngày tình nguyện: Tham gia hoạt động tình nguyện “Phòng, chống bạo lực học đường” ngày 16/03/2025; 01 ngày tình nguyện: Tham gia hoạt động tình nguyện “Phòng, chống tội phạm lừa đảo chiếm đoạt tài sản thông qua hình thức bán hàng và giao hàng trực tuyến” Trường Đại Học Sài Gòn ngày 01/03/2025; + 01 ngày tình nguyện: Tham gia hoạt động tình nguyện Trung thu sẻ chia 2024. | L17: Chứng chỉ IELTS Academic 6.0 overall do IDP Education tổ chức (28/05/2023); Đạt giải nhì Ring the golden bell 2025 do Liên chi Hội sinh viên Khoa Luật tố chức (đã có minh chứng); Quyết định số 48/QĐ-BTK của Ban chấp hành Đoàn Trường Đại học Sài Gòn ngày 23/10/2025 về việc tặng Giấy khen vì đã có thành tích xuất sắc trong công tác Hội và phong trào sinh viên Trường Đại học Sài Gòn năm học 2024 – 2025 Tham gia và đạt giấy chứng nhận “Xuất sắc Hoàn thành Nhiệm vụ tại Khu vực Asean Explorer – Sinh viên Đại học Sài Gòn tự tin hội nhập trong chuỗi hoạt động tại SGU’s day 2024. Tham gia seminar "Tìm hiểu về Tư pháp người chưa thành niên" do Trung tâm Đào tạo và Hợp tác Quốc tế với Tổng lãnh sự quán Đức tại Thành phố Hồ Chí Minh, thẩm phán, luật sư tại Đức ngày 05/08/2025 Giấy chứng nhận đã tham gia Vòng Bán kết 2 và đạt thành tích tốt trong Hội thi “thủ lĩnh sinh viên TP. Hồ Chí Minh" năm 2024. | N17: ĐẠT | O17: NGUYỄN HỮU THIỆN NHIÊN – 3123430131 – LUẬT – BẢNG KHAI THÀNH TÍCH.docx | P17: NGUYỄN HỮU THIỆN NHIÊN - 3123430131 - LUẬT - MINH CHỨNG THÀNH TÍCH (1).docx
A18: 13 | B18: Nguyễn Nữ Minh Thư | C18: 3123430178 | D18: LUẬT | E18: =VLOOKUP(C18,'Trang tính3'!$B$10:$H$377,7,0) -> 100 | F18: =VLOOKUP(C18,'Trang tính2'!$B$1:$D$175,3,0) -> 3.25 | H18: Giấy chứng nhận của Đảng ủy Trường Đại học Sài Gòn theo quyết định số 89-GCN/ĐU ngày 12/5/2025 về việc Đã đạt danh hiệu “Thanh niên tiên tiến Trường Đại học Sài Gòn làm theo lời Bác” năm học 2024- 2025 Danh hiệu “Thanh niên tiên tiến làm theo lời Bác” năm học 2024- 2025 do Đoàn khoa Luật cấp ngày 09/5/2025 Giấy chứng nhận của Chi bộ Sinh viên 1 ngày 03/8/2025 về việc Đã tích cực tham gia Cuộc thi “Giới thiệu các tác phẩm về Bác” năm 2025 Chứng nhận của Chi bộ Sinh viên 1 đã tích cực tham gia và đạt kết quả tốt các hoạt động trong Chương trình về nguồn 2024 “Hành trình lịch sử” Dâng hương, dâng hoa- Chủ đề “Hành trình Sử Việt” vào tháng 3/2025 | I18: Đề tài NCKH cấp Trường “Pháp luật về hoạt động cung ứng dịch vụ ví điện tử”, cấp trường, là thành viên tham gia, được đánh giá với số điểm 7.5, xếp loại Khá. Giấy chứng nhận của CLB Thực hành Pháp Luật theo quyết định số 01/2025/QĐ-BCN ngày 29/3/2025 tặng năm học 2024- 2025 “Thành viên đã có nhiều đóng góp quan trọng trong công tác tuyên truyền pháp luật tại CLB Thực Hành Pháp luật nhiệm kỳ 2023- 2025” | J18: Hội thao đảng viên Các Chi bộ sinh viên mở rộng trường Đại học Sài Gòn năm 2025 | K18: Giấy chứng nhận của Ban Chỉ huy chiến dịch theo quyết định số 01-QĐCN/ĐTN ngày 15/10/2024 về việc Đã tham gia và hoàn thành nhiệm vụ với vai trò là chiến sĩ Đội hình pháp luật. Giấy chứng nhận của BCH Đoàn khoa Luật ngày 02/4/2025 về việc Đã tham gia chương trình tình nguyện ngắn ngày ‘Hành trình xanh- Lan tỏa yêu thương” Tháng thanh niên năm 2025 Dâng hương, dâng hoa- Chủ đề “Hành trình Sử Việt” vào tháng 3/2025 Minh chứng 05 ngày tình nguyện: + Chương trình tình nguyện “ Trung thu sẻ chia” năm 2025 ( 02 ngày) + Ngày 3,4: Làm công tác chuẩn bị; Tổ chức gian hàng, trò chơi và các hoạt động trung thu cho trẻ em tại trường THCS Bàu Sen. (Hoạt động thiện nguyện không có GCN và Danh sách tham gia) + Ngày 5,6: Thiết kế Poster phân loại rác tại nguồn + Ngày 7,8: Vệ sinh và tô vẽ tường thuộc khuôn khổ Chương trình tình nguyện ngắn ngày ‘Hành trình xanh- Lan tỏa yêu thương” Tháng thanh niên năm 2025 Chương trình tình nguyện ngắn ngày ‘Hành trình xanh- Lan tỏa yêu thương” Tháng thanh niên năm 2025 Tham gia đội hình Văn hóa- Thể thao Lễ kỷ niệm 50 năm ngày giải phóng miền Nam, thống nhất nhất nước (30/4/1975- 30/4/2025). | L18: Chứng chỉ ngoại ngữ ngôn ngữ Tiếng anh bậc 3 do Trường Đại học Văn Lang cấp ngày 22/9/2025. Sân chơi Nói theo cách người trẻ chủ đề “Văn hóa giao tiếp và ứng xử sinh viên” (chưa cập nhật Danh sách) Cuộc thi “Ring the golden bell” 2025. Cuộc thi học thuật “Law’s challenge” năm 2025 do Đoàn khoa Luật tổ chức ngày 10/3/2025 Cuộc thi học thuật “Law’s Challege lần thứ V- năm 2025” do Đoàn khoa Luật tổ chức ngày 26/10/2025 Tọa đàm “Hành trang nghề Luật sư- những kỹ năng không thể thiếu” | N18: ĐẠT | O18: NGUYỄN NỮ MINH THƯ - 3123430178 - KHOA LUẬT - BẢNG MINH CHỨNG THÀNH TÍCH.docx | P18: NGUYỄN NỮ MINH THƯ - 3123430178 - BẢNG KHAI THÀNH TÍCH.docx
A19: 14 | B19: Nguyễn Thanh Bảo Tâm | C19: 3124430141 | D19: LUẬT | E19: =VLOOKUP(C19,'Trang tính3'!$B$10:$H$377,7,0) -> 93.7 | F19: =VLOOKUP(C19,'Trang tính2'!$B$1:$D$175,3,0) -> 3.34 | H19: Đạt danh hiệu “Thanh niên tiên tiến làm theo lời Bác” khoa Luật năm học 2024 - 2025. | I19: Tham gia và hoạt động tại câu lạc bộ Hạt giống khoa Luật (SLF). | J19: Đạt Danh hiệu “Thanh niên khỏe” trường Đại học Sài Gòn năm học 2024 – 2025. | K19: - Giấy chứng nhận ngày 2 tháng 4 năm 2025 của Ban chấp hành Đoàn trường Đại học Sài Gòn - Ban chấp hành Đoàn khoa Luật về việc đã tham gia chương trình tình nguyện ngắn ngày “Hành trình xanh - Lan tỏa yêu thương” Tháng Thanh niên 2025. (4 ngày) -Tham gia chương trình tình nguyện Trung thu sẻ chia năm 2025 ( 2 ngày ) | L19: Đạt B1 Aptis. Tham gia chương trình tập huấn “ Kỹ năng cho sinh viên” năm 2025 Giấy chứng nhận tham gia sân chơi hội nhập Ring the Golden bell năm 2025 | N19: ĐẠT | O19: NGUYỄN THANH BẢO TÂM - 3124430141 - LUẬT - BẢNG KHAI THÀNH TÍCH.docx | P19: _NGUYỄN THANH BẢO TÂM - 3124430141 - LUẬT - MINH CHỨNG THÀNH TÍCH CÁ NHÂN - 2025.docx
A20: 15 | B20: Nguyễn Thị Ngọc Tâm | C20: 3123430156 | D20: LUẬT | E20: =VLOOKUP(C20,'Trang tính3'!$B$10:$H$377,7,0) -> 99 | F20: =VLOOKUP(C20,'Trang tính2'!$B$1:$D$175,3,0) -> 3.59 | H20: Đạt danh hiệu “Thanh niên tiên tiến làm theo lời Bác” cấp khoa, thời gian tuyên dương ngày 21/5/2025. | I20: Thành viên Câu lạc bộ Hạt giống khoa Luật. Tham gia Nghiên cứu khoa học đề tài “Giải quyết tranh chấp thương mại bằng cơ chế liên thông hòa giải - trọng tài. Pháp luật một số nước và đề xuất cho pháp luật Việt Nam”, Cấp khoa, Vai trò Chủ nhiệm đề tài. Có bài viết vào Kỷ yếu Hội thảo Chuyên đề số 2 “Giải quyết tranh chấp sáng tạo bằng phương thức (Med - Arb) – kinh nghiệm áp dụng cho Việt Nam”, Diễn đàn khoa học trẻ “Luật học mùa xuân” lần thứ hai (2nd VSLF). Là thành viên đội thi LEX.VERI đạt giải ba tại hội thi THE CONNECTION 2024, Đoàn trường Đại học Luật TPHCM. | J20: Đạt danh hiệu “Thanh niên khỏe” Trường Đại học Sài Gòn năm học 2024 – 2025. | K20: Tham gia Chương trình tình nguyện Mùa hè xanh Đại học Sài Gòn lần thứ 32, 2025. Tham gia chương trình “Thứ bảy tình nguyện 2025” Tham gia chương trình Tiếp sức đến trường Đại học Sài Gòn năm 2025. Tham gia Chương trình Trung thu sẻ chia 2024 Tham gia Chương trình tình nguyện ngắn ngày “Dâng hương, dâng hoa Khu truyền thống cách mạng cuộc Tổng tiến công và nổi dậy xuân”. Tham gia Quyên góp ủng hộ đồng bào miền Bắc 2025. Tham gia chương trình tình nguyện “Hành trình xanh – Lan tỏa yêu thương”; | L20: Tham gia và đạt giải Ba tại sân chơi hội nhập “ Ring the golden bell 2025” - Tham gia tập huấn kỹ năng tự vệ cho sinh viên năm 2025”. - Tham gia “Tọa đàm nghiên cứu khoa học năm 2024 – 2025”, LCH SV khoa Luật, tổ chức ngày 15/6/2025, Ban tổ chức; - Giấy khen số 48/QĐ-BTK tặng vì đã có thành tích xuất sắc trong công tác Hội và phong trào sinh viên Trường Đại học Sài Gòn năm học 2024 – 2025. - Cuộc thi Law’s Challenge, Đoàn khoa Luật, Giải Ba. - Giấy chứng nhận Cuộc thi Hòa giải thương mại Việt Nam 2025 Vietnam Mediation Moot - V-Med 2025, VICMC phối hợp cùng VMC tổ chức và Học viện Tòa án hỗ trợ. | N20: ĐẠT | O20: NGUYỄN THỊ NGỌC TÂM - 3123430156 - LUẬT - BẢNG KHAI THÀNH TÍCH.docx | P20: NGUYỄN THỊ NGỌC TÂM - 3123430156 - LUẬT - BẢNG MINH CHỨNG THÀNH TÍCH.docx
A21: 16 | B21: Nguyễn Văn Thành | C21: 3124430149 | D21: LUẬT | E21: =VLOOKUP(C21,'Trang tính3'!$B$10:$H$377,7,0) -> 98.3 | F21: =VLOOKUP(C21,'Trang tính2'!$B$1:$D$175,3,0) -> 3.26 | H21: Đạt giải Ba hội thi Olympic về các môn khoa học Mác – Lênin, tư tưởng Hồ Chí Minh cấp trường năm 2025. | I21: Đạt giải Khuyến khích cuộc thi học thuật “Law Challenge năm 2024” do BCH Đoàn TNCS khoa Luật tổ chức; Đạt giải Khuyến khích cuộc thi học thuật “Law Challenge năm 2025” do BCH Đoàn TNCS khoa Luật tổ chức; Tham gia và hoạt động tích cực tại câu lạc bộ Hạt giống khoa Luật (SLF). | J21: Đạt Danh hiệu “Thanh niên khỏe” trường Đại học Sài Gòn năm học 2024 – 2025. | K21: Giấy khen số: 14 – QĐKT/ĐTN – VP ngày 08 tháng 8 năm 2025 của BCH Đoàn trường Đại học Sài Gòn về việc “Đã có đóng góp tích cực trong Chiến dịch tình nguyện Mùa hè xanh trường Đại học Sài Gòn lần thứ 32 - Năm 2025”; Tham gia và được nhận giấy chứng nhận của BCH Hội Sinh viên trường Đại học Sài Gòn trong chiến dịch Xuân tình nguyện năm 2025; Tham gia 5 ngày tình nguyện và được giấy chứng nhận của trung tâm hỗ trợ học sinh, sinh viên trong chương trình tình nguyện Tiếp sức mùa thi năm 2025. | L21: Đạt B2 Aptis. Tham gia sân chơi hội nhập “Ring The Golden Bell” năm 2025. Giấy khen số: 15 – QĐKT/ĐTN – VP ngày 24 tháng 10 năm 2025 của Ban Chấp hành Đoàn TNCS Hồ Chí Minh trường Đại học Sài Gòn về việc “Đã có đóng góp trong công tác Đoàn và phong trào thanh niên trường Đại học Sài Gòn năm học 2024 – 2025”. | N21: ĐẠT | O21: NGUYỄN VĂN THÀNH - 3124430149 - LUẬT - BẢNG KHAI THÀNH TÍCH.docx | P21: MẪU 03 - NGUYỄN VĂN THÀNH - 3124430149 - LUẬT - MINH CHỨNG THÀNH TÍCH CÁ NHÂN - 2025.docx
A22: 17 | B22: Trần Ngọc Linh | C22: 3123430088 | D22: LUẬT | E22: =VLOOKUP(C22,'Trang tính3'!$B$10:$H$377,7,0) -> 95.5 | F22: =VLOOKUP(C22,'Trang tính2'!$B$1:$D$175,3,0) -> 3.03 | L22: Không đạt tiêu chuẩn "Về ngoại ngữ" | N22: KHÔNG ĐẠT | O22: TRẦN NGỌC LINH - 3123430088 - LUẬT - BẢNG KHAI THÀNH TÍCH.docx | P22: TRẦN NGỌC LINH - 3123430088 - LUẬT - MINH CHỨNG THÀNH TÍCH .docx
A23: 18 | B23: Trần Ngọc Minh Anh | C23: 3122430014 | D23: LUẬT | E23: =VLOOKUP(C23,'Trang tính3'!$B$10:$H$377,7,0) -> 100 | F23: =VLOOKUP(C23,'Trang tính2'!$B$1:$D$175,3,0) -> 3.57 | H23: Sao tháng “Thanh niên SGU nghĩ đúng - sống đẹp” năm 2025 Đạt danh hiệu Thanh niên tiên tiến làm theo lời Bác khoa Luật năm học 2024 -2025. Đạt danh hiệu Thanh niên tiên tiến làm theo lời Bác trường Đại học Sài Gòn năm học 2024 -2025. Đạt Giải Ba Bảng Đội tuyển “HỘI THI OLYMPIC CÁC MÔN KHOA HỌC MÁC - LÊNIN VÀ TƯ TƯỞNG HỒ CHÍ MÌNH TRƯỜNG ĐẠI HỌC SÀI GÒN” NĂM 2025 | I23: - Chủ nhiệm CLB Hạt giống khoa Luật - Khoa Luật Trường Đại học Sài Gòn - Giải khuyến khích cuộc thi Law’s Conquerors 2025, do Khoa Luật trường Đại học Kinh tế (UEF) tổ chức Giấy chứng nhận thành viên hoạt động tích cực tại CLB SLF | J23: - Đạt danh hiệu “ Thanh niên khỏe” tại Hội Thao Chào mừng Đại hội Đại biểu Hội Sinh viên Việt Nam trường Đại học Sài Gòn lần thứ IX, nhiệm kỳ 2025 -2028. | K23: - Tham gia chiến dịch Xuân Tình nguyện trường Đại học Sài Gòn lần thứ 17 năm 2025 - Tham gia chiến dịch Mùa hè Xanh trường Đại học Sài Gòn lần thứ 32 năm 2025 - Giấy khen của Hội Sinh viên trường số vì đã đạt thành tích xuất sắc trong Chiến dịch Mùa hè Xanh trường Đại học Sài Gòn lần thứ 17 năm 2025 | L23: Đạt trình độ Tiếng Anh VSTEP B2 Tham gia tập huấn kỹ năng tự vệ cho sinh viên năm 2025 Giấy khen của Hội Sinh viên trường số Số: 14-QĐKT/ĐTN-VP ngày 08 tháng 08 năm 2025 vì đã đạt thành tích xuất sắc trong Chiến dịch Mùa hè Xanh trường Đại học Sài Gòn lần thứ 17 năm 2025. Giấy khen của Hội Sinh viên trường số: 48/QĐ-BTK ngày 23 tháng 10 năm 2025 vì đã đạt thành tích xuất sắc trong công tác Hội và phong trào sinh viên khoa Luật nhiệm kỳ 2024 - 2025 + Giấy khen của Hội Sinh viên trường số : 16/QĐ-BTK ngày 15 tháng 4 năm 2025 vì đã đạt danh hiệu Cán bộ Hội tiêu biểu năm học 2024 - 2025 Tham gia Hội thi Thủ lĩnh Sinh viên thành phố Hồ Chí Minh năm 2025 ( Top 50) | N23: ĐẠT | O23: MẪU 01 - TRẦN NGỌC MINH ANH - 2024-2025.docx | P23: MẪU 03 - TRẦN NGỌC MINH ANH - 2025.docx
A24: 19 | B24: Trần Nguyễn Thùy Trang | C24: 3124430177 | D24: LUẬT | E24: =VLOOKUP(C24,'Trang tính3'!$B$10:$H$377,7,0) -> 92.3 | F24: =VLOOKUP(C24,'Trang tính2'!$B$1:$D$175,3,0) -> 3.31 | H24: - Thanh niên tiên tiến khoa Luật làm theo lời Bác năm học 2024-2025 | I24: - Diễn đàn khoa học trẻ “Luật học mùa xuân” lần thứ hai, năm 2025 - Thành viên đội thi TNT tham gia cuộc thi Law’s Challenge 2025 | J24: - Đạt danh hiệu “Thanh niên khỏe” Trường Đại học Sài Gòn năm học 2024 – 2025 | K24: - Chương trình “Xuân yêu thương - Vì nụ cười trẻ thơ” năm 2025 Chương trình “Xuân nhân ái - Hái yêu thương 2025” lần thứ III Chương trình tình nguyện “Trung thu sẻ chia 2025” Tham gia chương trình “Thứ bảy tình nguyện 2025” - Chương trình tình nguyện “Hành trình xanh – Lan tỏa yêu thương” | L24: Tham gia Sân chơi hội nhập “Ring the Golden Bell 2025” - Toạ đàm “Kỹ năng tự vệ cho sinh viên” - Tọa đàm “Hành trang nghề luật sư - Những kỹ năng không thể thiếu” - Giấy khen số 48/QĐ-BTK tặng vì đã có thành tích xuất sắc trong công tác Hội và phong trào sinh viên Trường Đại học Sài Gòn năm học 2024-2025 | N24: ĐẠT | O24: TRẦN NGUYỄN THÙY TRANG - 3124430177 - KHOA LUẬT - BẢNG KHAI THÀNH TÍCH.pdf.pdf | P24: TRẦN NGUYỄN THÙY TRANG - 3124430177 - KHOA LUẬT - MINH CHỨNG THÀNH TÍCH.pdf.pdf
A25: 20 | B25: Trịnh Tú Hảo | C25: 3122430044 | D25: LUẬT | E25: =VLOOKUP(C25,'Trang tính3'!$B$10:$H$377,7,0) -> 94.5 | F25: =VLOOKUP(C25,'Trang tính2'!$B$1:$D$175,3,0) -> 3.11 | H25: Đạt danh hiệu Thanh niên tiên tiến làm theo lời Bác khoa Luật năm học 2024 -2025. | I25: - NCKH: Tội lạm dụng chức vụ quyền hạn nhằm chiếm đoạt tài sản theo pháp luật Việt Nam” (80/100) đạt loại Tốt. - Thành viên CLB SLF ( Hạt giống khoa Luật) | J25: - Đạt danh hiệu “ Thanh niên khỏe” tại Hội Thao Chào mừng Đại hội Đại biểu Hội Sinh viên Việt Nam trường Đại học Sài Gòn lần thứ IX, nhiệm kỳ 2025 -2028. | K25: - Tham gia chiến dịch Xuân Tình nguyện lần thứ 17 năm 2025 - Tham gia chương trình Tiếp sức đến trường 2025 | L25: Đạt trình độ Tiếng Anh Aptis B1 +Tham gia tập huấn kỹ năng tự vệ cho sinh viên năm 2025 Giấy khen của Hội Sinh viên trường số 02/QĐ – BTK ngày 25/01/2025 vì đã đạt thành tích xuất sắc trong Chiến dịch Xuân tình nguyện trường Đại học Sài Gòn lần thứ 17 năm 2025. + Giấy khen của Hội Sinh viên trường số 04/QĐ – BTK ngày 11/03/2025 vì đã đạt thành tích xuất sắc trong công tác Hội và phong trào sinh viên khoa Luật nhiệm kỳ 2023 -2025 Giấy khen của Hội Sinh viên trường số 16/QĐ – BTK ngày 15/4/2025 vì đã đạt danh hiệu cán bộ tiêu biểu. + Bằng khen của Ban Chấp hành hội Sinh viên Thành phố Hồ Chí Minh số 33/QĐ- TĐKT ngày 10/10/2025 vì đã có thành tích xuất sắc trong công tác Hội và phong trào sinh viên Thành phố năm học 2024 – 2025. +Tham gia Hội thi Thủ lĩnh Sinh viên thành phố Hồ Chí Minh năm 2025 ( Top 50) | N25: ĐẠT | O25: TRỊNH TÚ HẢO - 3122430044 - KHOA LUẬT - BẢNG KHAI THÀNH TÍCH.docx | P25: TRỊNH TÚ HẢO - 3122430044 - KHOA LUẬT - MINH CHỨNG THÀNH TÍCH.docx
A26: 21 | B26: Võ Thanh Thảo | C26: 3123430163 | D26: LUẬT | E26: =VLOOKUP(C26,'Trang tính3'!$B$10:$H$377,7,0) -> 92.5 | F26: =VLOOKUP(C26,'Trang tính2'!$B$1:$D$175,3,0) -> 3.66 | L26: HN. Tọa đàm "Sinh viên 5 tốt" Không phải là hoạt động hội nhập. => Thiếu tiêu chuẩn "HĐ HN" | N26: KHÔNG ĐẠT | O26: VÕ THANH THẢO - 3123430163 - LUẬT - BẢNG KHAI THÀNH TÍCH - 2024 -2025.docx | P26: VÕ THANH THẢO - 3123430163 - LUẬT - MINH CHỨNG THÀNH TÍCH - 2024 - 2025.docx
A27: 22 | B27: Nguyễn Trương Diễm Ngọc | C27: 3122430118 | D27: LUẬT | E27: 99 | F27: 3.89 | H27: Kết quả đánh giá chất lượng Đoàn viên năm học 2024 - 2025 đạt Hoàn thành xuất sắc nhiệm vụ. Đạt danh hiệu “Thanh niên tiên tiến Trường Đại học Sài Gòn làm theo lời Bác” năm học 2024 – 2025. | I27: Có bài viết tham luận bằng tiếng Anh “ASEAN's Path to Sustainable Development: Navigating International Relations, Legal Frameworks in the Context of Globalization and Modernization” trình bày tại Hội thảo Quốc tế do Trường Đại học Luật Thành phố Hồ Chí Minh tổ chức tháng 7 năm 2025. | J27: Đạt danh hiệu “Thanh niên khỏe” cấp Trường năm 2024 và năm học 2024 - 2025. | K27: Nhận Giấy khen số 43/QĐ-BTK ngày 08/08/2025 của Hội Sinh viên trường vì thành tích tốt trong Chương trình Tiếp sức mùa thi năm 2025. Tham gia và hoàn thành Chương trình Tiếp sức mùa thi trường Đại học Sài Gòn năm 2025. Tham gia chương trình tình nguyện “Trung thu sẻ chia 2024”, “Xuân yêu thương” tại Mái ấm Tâm Đức và “Xuân nhân ái - Hái yêu thương” tại Tịnh xá Ngọc Quang. Tham gia hoạt động “Thứ bảy tình nguyện”, chương trình “Hành trình xanh” và tham quan Bảo tàng Hồ Chí Minh (Bến Nhà Rồng). | L27: Đạt trình độ ngoại ngữ tiếng Anh chứng chỉ TOEIC trình độ B2. Tham gia Ngày hội Sinh viên với ngoại ngữ năm 2025 chủ đề "GenZith Horizon" và chương trình Giao lưu tặng quà cho sinh viên Lào. Xuất sắc lọt vào Vòng Chung kết cuộc thi Law's Conquerors 2025 do Trường Đại học Kinh tế - Tài chính Thành phố Hồ Chí Minh và Công ty Luật TNHH TA PHA tổ chức. Xuất sắc hoàn thành nhiệm vụ tại khu vực “ASEAN Explorer - Sinh viên Đại học Sài Gòn tự tin hội nhập” trong Ngày hội Tân sinh viên SGU's Day 2024. Hoàn thành khóa tập huấn Kỹ năng AI dành cho Cán bộ Đoàn – Hội và khóa học “Thanh niên tình nguyện hỗ trợ chính quyền địa phương hai cấp” của Trung ương Đoàn. Tham gia chương trình kỹ năng nghề nghiệp “Khảo sát doanh nghiệp yêu thích 2025 – ENTERPRISE OF CHOICE”. Tham gia tập huấn An toàn giao thông và chuyên đề Ứng dụng kỹ năng số cho sinh viên năm 2024. | M27: Đề xuất tiêu biểu | N27: ĐẠT | O27: 17.NGUYỄN TRƯƠNG DIỄM NGỌC .docx | P27: 17. NGUYỄN TRƯƠNG DIỄM NGỌC
A28: 23 | B28: Nguyễn Tấn Tài | C28: 3123430154 | D28: LUẬT | E28: 99\ | F28: 3.76 | H28: Kết quả đánh giá chất lượng Đoàn viên năm học 2024 - 2025 đạt Hoàn thành xuất sắc nhiệm vụ. Là thành viên chính thức tham dự bảng đội tuyển Hội thi Olympic các môn khoa học Mác - Lênin và Tư tưởng Hồ Chí Minh trường Đại học Sài Gòn năm 2025. | I28: Có bài viết khoa học “Tinh gọn Hội đồng nhân dân trong bối cảnh mới - Thực trạng và một số kiến nghị” đăng trên kỷ yếu Hội thảo khoa học cấp trường VSLF do Đại học Luật - Đại học Quốc gia Hà Nội tổ chức vào tháng 04/2025. | J28: Đạt danh hiệu “Thanh niên khỏe” trường Đại học Sài Gòn năm 2025 theo Giấy chứng nhận số 02 - GCN - BTK của Ban Thư ký Hội Sinh viên trường | K28: Nhận Giấy khen số 02/QĐ-BTK ngày 25/01/2025 của Hội Sinh viên trường vì thành tích xuất sắc trong Chiến dịch Xuân Tình nguyện lần thứ 17 năm 2025. Nhận Giấy khen của Chủ tịch Ủy ban nhân dân Phường 12, Quận 6 vì thành tích xuất sắc trong công tác Đoàn và phong trào thanh thiếu nhi năm 2024. Tham gia và hoàn thành Chiến dịch Xuân Tình nguyện trường Đại học Sài Gòn các năm 2024 và 2025. Tham gia các chương trình tình nguyện cộng đồng như: Trung thu sẻ chia năm 2024, Xuân yêu thương tại mái ấm Tâm Đức, và Xuân nhân ái - Hái yêu thương tại Tịnh xá Ngọc Quang. Tham gia hoạt động Thứ 7 tình nguyện, chương trình Hành trình xanh, chương trình Lan tỏa yêu thương và viếng văn bia tưởng niệm Xuân Mậu Thân 1968. | L28: Điểm trung bình các học phần Tiếng Anh đạt kết quả cao: Tiếng Anh 1 (9.0), Tiếng Anh 2 (9.3), và Tiếng Anh 3 (8.4). Tham gia Chương trình giao lưu và tặng quà cho sinh viên Lào tại Ký túc xá Sinh viên Lào Thành phố Hồ Chí Minh ngày 01/02/2025. Tham gia hỗ trợ đón tiếp đoàn Đại biểu Tàu thanh niên Đông Nam Á Nhật Bản (SSEAYP) năm 2024 trong chương trình Home Matching tại Quận 6. Xuất sắc hoàn thành nhiệm vụ tại khu vực “ASEAN Explorer - Sinh viên Đại học Sài Gòn tự tin hội nhập” trong Ngày hội Tân Sinh viên SGU's Day 2024. Đạt danh hiệu Cán bộ Hội tiêu biểu năm học 2024 - 2025. Nhận Giấy khen vì có thành tích xuất sắc trong công tác Hội và phong trào sinh viên khoa Luật nhiệm kỳ 2023 - 2025 và năm học 2023 - 2024. Hoàn thành chuyên đề “Ứng dụng kỹ năng số cho sinh viên năm 2024” và tập huấn “An toàn giao thông và kỹ năng phòng tránh va chạm trong hoạt động tình nguyện”. | M28: Đề xuất tiêu biểu | N28: ĐẠT | O28: 18.NGUYỄN TẤN TÀI - BẢNG KHAI.docx | P28: 18. NGUYỄN TẤN TÀI
A29: 24 | B29: Đào Trần Thanh | C29: 3121430166 | D29: LUẬT | E29: 100 | F29: 3.63 | H29: Kết quả đánh giá chất lượng Đoàn viên cuối năm đạt Hoàn thành xuất sắc nhiệm vụ. Nhận Giấy khen của Ban Chấp hành Đảng bộ trường Đại học Sài Gòn vì thành tích trong “Học tập và làm theo tư tưởng, đạo đức, phong cách Hồ Chí Minh” ngày 12/05/2025. Được vinh danh là Gương điển hình tiên tiến trường Đại học Sài Gòn giai đoạn 2020 - 2025 theo Quyết định số 1416/QĐ-ĐHSG ngày 04/06/2025. Đạt danh hiệu "Thanh niên tiên tiến trường Đại học Sài Gòn" năm học 2023 - 2024. Là Đảng viên chính thức từ ngày 09/11/2024. | I29: Đạt giải Nhì Giải thưởng sinh viên nghiên cứu khoa học - Euréka lần thứ 26 năm 2024 cấp Thành phố và cấp Trường. Tốt nghiệp đại học loại Giỏi chuyên ngành Luật. Đạt học bổng Khuyến khích học tập qua nhiều kỳ học. | J29: Đạt giải Nhì bộ môn cầu lông nam nữ tại Hội thao chào mừng Đại hội đại biểu Hội Sinh viên Việt Nam trường Đại học Sài Gòn lần thứ IX năm 2025. Đạt danh hiệu "Thanh niên khỏe" trường Đại học Sài Gòn năm 2024 theo Giấy chứng nhận số 02-QĐGCN/HSV ngày 05/10/2024. | K29: Nhận Bằng khen của Ban Chấp hành Trung ương Hội Sinh viên Việt Nam vì thành tích xuất sắc trong Chiến dịch tình nguyện Mùa hè xanh năm 2024. Nhận Bằng khen của Ban Chấp hành Hội Sinh viên Thành phố Hồ Chí Minh vì thành tích xuất sắc trong Chiến dịch Xuân tình nguyện lần thứ 17 năm 2025. Hoàn thành Chiến dịch tình nguyện Mùa hè xanh năm 2024 và Chiến dịch Xuân tình nguyện lần thứ 17 năm 2025. Tham gia đầy đủ 05 ngày tình nguyện trong năm học theo xác nhận của Hội Sinh viên trường. | L29: Đạt chứng chỉ tiếng Anh Vstep trình độ B1 theo khung tham chiếu châu Âu. Nhận Bằng khen của Ban Chấp hành Trung ương Hội Sinh viên Việt Nam vì thành tích xuất sắc trong công tác Hội và phong trào sinh viên năm học 2024 - 2025. Tham gia Ngày hội Sinh viên với ngoại ngữ English Camp 2025 do Hội Sinh viên Thành phố Hồ Chí Minh tổ chức. Tham gia Chương trình giao lưu và tặng quà cho sinh viên Lào tại Ký túc xá Sinh viên Lào Thành phố Hồ Chí Minh ngày 01/02/2025. Xuất sắc hoàn thành nhiệm vụ tại khu vực "ASEAN Explorer - Sinh viên Đại học Sài Gòn tự tin hội nhập" năm 2024. Hoàn thành Chương trình "Phổ cập AI" dành cho cán bộ Đoàn - Hội do Trung ương Đoàn tổ chức. Tham gia tập huấn chuyên đề An toàn giao thông và chuyên đề Ứng dụng kỹ năng số cho sinh viên trường Đại học Sài Gòn. Có chứng chỉ Ứng dụng Công nghệ thông tin cơ bản. | M29: Đề xuất tiêu biểu | N29: ĐẠT | P29: 19. ĐÀO TRẦN THANH
A30: 25 | B30: Đặng Thị Cúc | C30: 3122350030 | D30: VĂN HOÁ VÀ DU LỊCH | E30: =VLOOKUP(C30,'Trang tính3'!$B$10:$H$377,7,0) -> 98.5 | F30: =VLOOKUP(C30,'Trang tính2'!$B$1:$D$175,3,0) -> 2.83 | H30: Số 133-GCN/ĐU ngày 12/5/2025 Đạt danh hiệu Thanh niên tiên tiến trường Đại học Sài Gòn làm theo lời Bác năm học 2024-2025 Số 01-GCN/ĐTN-VHDL ngày 20/3/2025 Đạt danh hiệu Điển hình Thanh niên tiên tiến khoa Văn hoá và Du lịch làm theo lời Bác năm học 2024 – 2025 | I30: Đã có đóng góp tích cực cho các hoạt động của CLB Truyền thông và Đối ngoại HKII năm học 2024-2025 | J30: Giấy chứng nhận Thanh niên khỏe trường Đại học Sài Gòn năm học 2024 - 2025 | K30: Đội trưởng Đội hình Sắc màu Văn hoá thuộc chiến dịch tình nguyện Mùa hè xanh trường Đại học Sài Gòn lần thứ 32, năm 2025 | L30: Giấy chứng nhận đã hoàn thành nhiệm vụ tại khu vực “ASEAN Explorer – Sinh viên Đại học Sài Gòn tự tin hội nhập” Số 15-QĐKT/ĐTN-VP ngày 24/10/2025 Khen thưởng Đã có đóng góp tích cực trong công tác Đoàn và phong trào thanh niên Trường Đại học Sài Gòn năm học 2024-2025 Đạt chứng chỉ B1 Aptis Esol, cấp vào ngày 31.7.2025 bởi tổ chức British Council | N30: ĐẠT | O30: ĐẶNG THỊ CÚC - 3122350030 - VĂN HOÁ VÀ DU LỊCH - BẢNG KHAI THÀNH TÍCH.docx | P30: ĐẶNG THỊ CÚC - 3122350030 - VĂN HOÁ VÀ DU LỊCH - MINH CHỨNG THÀNH TÍCH.docx | Q30: 30 SV5T KHOA 6 SV5TTB KHOA
A31: 26 | B31: Hà Thái Toàn | C31: 3123350177 | D31: VĂN HOÁ VÀ DU LỊCH | E31: =VLOOKUP(C31,'Trang tính3'!$B$10:$H$377,7,0) -> 100 | F31: =VLOOKUP(C31,'Trang tính2'!$B$1:$D$175,3,0) -> 3.03 | L31: Thiếu tiêu chuẩn "Về ngoại ngữ" | N31: KHÔNG ĐẠT | O31: MẪU 1 - HÀ THÁI TOÀN - 3123350177 - BẢNG KHAI THÀNH TÍCH..docx | P31: MẪU 02 - HÀ THÁI TOÀN - 3123350177 -MINH CHỨNG THÀNH TÍCH CÁ NHÂN - 2025.docx
A32: 27 | B32: Huỳnh Thị Xu Kiên | C32: 3122540036 | D32: VĂN HOÁ VÀ DU LỊCH | E32: =VLOOKUP(C32,'Trang tính3'!$B$10:$H$377,7,0) -> 96.5 | F32: =VLOOKUP(C32,'Trang tính2'!$B$1:$D$175,3,0) -> 3.74 | H32: Thiếu MC tiêu chuẩn khác | K32: Không đủ 05 ngày tình nguyện | N32: KHÔNG ĐẠT | O32: HUỲNH THỊ XU KIÊN – 3122540036 – VĂN HÓA VÀ DU LỊCH – BẢNG KHAI THÀNH TÍCH.docx | P32: HUỲNH THỊ XU KIÊN_3122540036 – VĂN HÓA VÀ DU LỊCH – MINH CHỨNG THÀNH TÍCH.docx
A33: 28 | B33: Khưu Mỹ Hoàng | C33: 3122570045 | D33: VĂN HOÁ VÀ DU LỊCH | E33: =VLOOKUP(C33,'Trang tính3'!$B$10:$H$377,7,0) -> 99 | F33: =VLOOKUP(C33,'Trang tính2'!$B$1:$D$175,3,0) -> 3.76 | H33: - Hoàn thành Lớp Bồi Dưỡng Nhận Thức Đảng 16-20/8/2025 Hoàn thành nội dung học tập nghị quyết Đại hội Đoàn toàn quốc lần thứ XII, nhiệm kỳ 2022-2027 | I33: Giải thưởng Best Participation Award in the “Discover- The magic of Travel” of the Third “Tourism+Chinese Language” Programme | J33: Tham gia Sinh viên khỏe tại SGU day ( 19/10/2025) | K33: Tình nguyện viên tháp tùng Đại biểu quốc tế tại Lễ kỷ niệm 50 năm ngày giải phóng miền Nam, thống nhất đất nước ( 30/04/1975-30/04/2025) : Tháp tùng hai bác đại biểu Mr JOSE MIGUEL MEJIA ABREU- Tổng Bí Thư Đảng MIU, Cộng Hòa Dominica và Ms ALTAGRACIA MARHA PEREZ CAMPUSANO - Bí thư phụ trách đối ngoại Cộng hòa Dominica. Tháp tùng Đoàn đại biểu tại Đại lễ Phật Đản Vesak 2025 (05-09/5/2025) Tình nguyện viên hỗ trợ thuộc Team Tổ Thư ký ( Văn phòng- Trung tâm xúc tiến du lịch TPHCM) tại sự kiện Hội chợ du lịch quốc tế TP HCM-ITE HCMC 2025 ( 20/8-5/9/2025) Tình nguyện viên lĩnh vực khoa học -xã hội của Giải thưởng nghiên cứu khoa học Euréka lần thứ 26 năm 2024 ( 11-12/2024) Tình nguyện viên hỗ trợ thuộc team Lễ tân - Hậu cần ( Phòng Tổ chức sự kiện- Trung tâm xúc tiến du lịch TPHCM) tại sự kiện Hội chợ du lịch quốc tế TP HCM-ITE HCMC 2024( 01-07/9/2024) | L33: - Chứng chỉ tiếng Trung HSK5 ( 4/2024) Tiếng Anh 1 : 10 Tiếng Anh 2:10 Tiếng Anh 3: 10 * Tham gia training nghiệp vụ tại Sở Du Lịch ( 09/08/2025) và Sở Ngọại Vụ ( 23/08/2025) cho nhóm Tình nguyện viên hỗ trợ thuộc Team Tổ Thư ký ( Văn phòng- Trung tâm xúc tiến du lịch TPHCM) tại sự kiện Hội chợ du lịch quốc tế TP HCM- ITE HCMC 2025 ( 20/8-5/9/2025) - Đoàn viên tiêu biểu năm học 2024-2025 Tháp tùng Đại biểu quốc tế tại A50 Tham gia International Perspectives Series Webinar: Laboratory Prediction Energy Control System based on Artificial Intelligence held on 3 October, 2024 (3)Tham gia International Experts Sharing webinar entitled Digital Economy and Global Sustainable Development held on 11 October, 2024 (4)Tham gia “ Cultivation Techniques of Rice -Integrated Management of Rice Pests and Diseases” on 25 October,2024 (5)Tham gia “No Cap, Just Clarity, The Real Deal on Explainable AI(XAI)”on 27 September,2024 (6)Tham gia “Cultivation Technology of Annual and Biennial Flower” on 27 September,2024 Đạt giấy chứng nhận xuất sắc tham gia trại đông online của trường đại học Chính Pháp Thượng Hải (Trung Quốc), 10-12/2024 Đạt giấy chứng nhận xuất sắc tham gia trại xuân online của trường đại học Hà Nam ( Trung Quốc), 15-18/01/2025 Hoàn thành xuất sắc 3 khóa học online tại Học Viện Hoa Kiều ( Chiết Giang, Trung Quốc): (10) Đạt giấy chứng nhận Hoàn thành xuất sắc trại hè trường Đại học Lan Châu (Trung Quốc) | N33: ĐẠT | O33: KHƯU MỸ HOÀNG_3122570045_KHOA VĂN HÓA VÀ DU LỊCH_BẢNG KHAI THÀNH TÍCH.docx | P33: KHƯU MỸ HOÀNG_3122570045_KHOA VĂN HÓA VÀ DU LỊCH_MINH CHỨNG THÀNH TÍCH.docx
A34: 29 | B34: Lê Hoàng Vinh | C34: 3122570149 | D34: VĂN HOÁ VÀ DU LỊCH | E34: =VLOOKUP(C34,'Trang tính3'!$B$10:$H$377,7,0) -> 100 | F34: =VLOOKUP(C34,'Trang tính2'!$B$1:$D$175,3,0) -> 3.55 | I34: Thiếu tiêu chuẩn khác | L34: Thiếu tiêu chuẩn kỹ năng | N34: KHÔNG ĐẠT | O34: LÊ HOÀNG VINH - 3122570149 - BẢNG KHAI THÀNH TÍCH CÁ NHÂN - 2024-2025.docx | P34: LÊ HOÀNG VINH - 3122570149 - MINH CHỨNG THÀNH TÍCH CÁ NHÂN - 2025.docx
A35: 30 | B35: Nguyễn Phạm Huy Phúc | C35: 3122350184 | D35: VĂN HOÁ VÀ DU LỊCH | E35: =VLOOKUP(C35,'Trang tính3'!$B$10:$H$377,7,0) -> 99 | F35: =VLOOKUP(C35,'Trang tính2'!$B$1:$D$175,3,0) -> 3.53 | H35: Thiếu tiêu chuẩn khác | I35: Thiếu tiêu chuẩn khác | J35: MC không hợp lệ | N35: KHÔNG ĐẠT | O35: NGUYỄN PHẠM HUY PHÚC - 3122350184 - KHOA VĂN HÓA VÀ DU LỊCH - BẢNG KHAI THÀNH TÍCH.docx | P35: NGUYỄN PHẠM HUY PHÚC - 3122350184 - KHOA VĂN HÓA VÀ DU LỊCH - MINH CHỨNG THÀNH TÍCH.docx
A36: 31 | B36: Nguyễn Thị Tuyết Ngân | C36: 3121540074 | D36: VĂN HOÁ VÀ DU LỊCH | E36: =VLOOKUP(C36,'Trang tính3'!$B$10:$H$377,7,0) -> 82 | F36: =VLOOKUP(C36,'Trang tính2'!$B$1:$D$175,3,0) -> 3.53 | H36: * Đạt danh hiệu: Sao tháng “Thanh niên SGU nghĩ đúng - sống đẹp”. | I36: Tham gia CLB Tiếng Anh khoa Văn hóa & Du lịch - Republic Of English. | J36: - Tham gia Sân chơi “Thanh niên khỏe”: số thứ tự 1384 | K36: Tham gia Chiến dịch Xuân Tình nguyện 2025 - Đội hình Xuân Sẻ Chia: - Ngày 1: Tham gia hỗ trợ hiến máu ngày 22/03/2025: số thứ tự số 1. - Ngày 2: Tham gia dọn vệ sinh kênh rạch cùng Sài Gòn Xanh của Đội Công tác Xã hội tại Tam Phú, Thủ Đức ngày 16/03/2025 - Ngày 3: Tổ chức, tham gia Hành trình Yêu thương 07 của Đội CTXH tại Trung tâm Bảo trợ Người già Thiên Ân ngày 08/03/2025 Ngày 4: Tổ chức, tham gia Hưởng ứng Giờ Trái Đất 2025 - Hướng dẫn di chuyển bằng Metro với Chủ đề “Chiến dịch Xanh, Tương lai Xanh” ngày 15/03/2025 - Ngày 5: Tham gia hỗ trợ thả hoa đăng Đại lễ Vesak 2025 ngày 06/05/2025: | L36: - Đạt chứng chỉ: Aptis B1: - Tham gia hỗ trợ thả hoa đăng trong Đại lễ Vesak 2025. Giấy khen của Ủy ban Hội Liên hiệp Thanh niên Việt Nam Quận 3 theo quyết định số 21/QĐ- UBH ngày 28/05/2025 về việc Đã đạt danh hiệu “Đã có thành tích xuất sắc trong hoạt động Đội Công tác Xã hội Quận 3 nhiệm kỳ 2022 - 2025”. | N36: ĐẠT | O36: BẢNG KHAI THÀNH TÍCH CÁ NHÂN - SV5T CẤP TRƯỜNG - 2024-2025 - NGUYỄN THỊ TUYẾT NGÂN.pdf | P36: MINH CHỨNG THÀNH TÍCH CÁ NHÂN - SV5T TRƯỜNG ĐHSG - 2025 - NGUYỄN THỊ TUYẾT NGÂN..pdf
A37: 32 | B37: Thông Thị Diệu Hiền | C37: 3123570037 | D37: VĂN HOÁ VÀ DU LỊCH | E37: =VLOOKUP(C37,'Trang tính3'!$B$10:$H$377,7,0) -> 99 | F37: =VLOOKUP(C37,'Trang tính2'!$B$1:$D$175,3,0) -> 3.33 | H37: - Giấy chứng nhận thanh niên tiên tiến Trường Đại học Sài Gòn làm theo lời Bác năm học 2024 - 2025 ngày 12/5/2025 của Đảng ủy Trường Đại học Sài Gòn. - Giấy chứng nhận Điển hình Thanh niên tiên tiến khoa Văn hóa và Du lịch làm theo lời Bác năm học 2024 - 2025 ngày 20 tháng 03 năm 2025 của BTV Đoàn khoa VH&DL. - Đạt danh hiệu “Cán bộ Đoàn tiêu biểu” năm học 2024-2025, Kỷ niệm 94 năm Ngày thành lập Đoàn TNCS Hồ Chí Minh (26/03/1931- 26/03/2025), ngày 18/4/2025 của Ban Chấp hành Đoàn trường Đại học Sài Gòn. | I37: - Giấy chứng nhận thành viên CLB ROE - CLB tiếng Anh khoa Văn hóa và Du lịch | J37: - Tham gia Sân chơi “Thanh niên khỏe” trong khuôn khổ ngày hội Tân sinh viên năm 2025 với chủ đề “SGU’s Day 2025” | K37: - Đã tham gia và đạt danh hiệu “Chiến sĩ giỏi tiêu biểu “ Chiến dịch tình nguyện mùa hè xanh Trường Đại học Sài Gòn lần thứ 32 năm 2025 của Ban chỉ huy chiến dịch Mùa hè xanh Trường Đại học Sài Gòn. - Giấy chứng nhận “ Là chiến sĩ đội hình Xuân sẻ chia” Chiến dịch Xuân tình nguyện Trường Đại học Sài Gòn của Ban chỉ huy Chiến dịch Xuân tình nguyện Trường Đại học Sài Gòn lần thứ 17 năm 2025. - Giấy chứng nhận “Là sinh viên tình nguyện Chương trình “TIẾP SỨC MÙA THI” năm 2025, ngày 01 tháng 7 năm 2025 của Giám đốc Trung tâm hỗ trợ học sinh, sinh viên Thành Phố Hồ Chí Minh. - Giấy xác nhận “ Đã tham gia 07 ngày tình nguyện Chương trình “TIẾP SỨC MÙA THI 2025” do Hội sinh viên Việt Nam Tp.Hồ Chí Minh và Trung tâm hỗ trợ học sinh sinh viên Thành phố Hồ Chí Minh Tổ Chức”, ngày 01 tháng 7 năm 2025, của Giám đốc Trung tâm hỗ trợ học sinh, sinh viên Thành Phố Hồ Chí Minh. | L37: Chứng chỉ IELTS - Tiếng Anh - Trình độ: B2 (5.5). Đơn vị cấp: IDP. Thời gian cấp: 23/4/2023. - Giấy khen “Đã có đóng góp tích cực trong công tác Đoàn và phong trào Thanh niên Trường Đại học Sài Gòn năm học 2024 - 2025” của BCH Đoàn Trường Đại học Sài Gòn ngày 24/10/2025 - Tham gia cuộc thi trắc nghiệm trực tuyến “Tự hào ngoại giao Việt Nam vững bước tiến vào kỷ nguyên mới của Thành Đoàn TP.Hồ Chí Minh ngày 29/8/2025 - Đạt 20/30 điểm, nằm trong TOP 50. | N37: ĐẠT | O37: MẪU 01 - BẢNG KHAI THÀNH TÍCH CÁ NHÂN - 2024-2025.docx | P37: MẪU 03 - MINH CHỨNG THÀNH TÍCH CÁ NHÂN - 2025.docx
A38: 33 | B38: Trang Võ Thảo Nhi | C38: 3122570086 | D38: VĂN HOÁ VÀ DU LỊCH | E38: =VLOOKUP(C38,'Trang tính3'!$B$10:$H$377,7,0) -> 100 | F38: =VLOOKUP(C38,'Trang tính2'!$B$1:$D$175,3,0) -> 3.49 | I38: Thiếu tiêu chuẩn khác | N38: KHÔNG ĐẠT | O38: TRANG VÕ THẢO NHI_3122570086_KHOAVHVDL_BẢNG KHAI THÀNH TÍCH.docx | P38: TRANG VÕ THẢO NHI_3122570086_KHOAVHVDL_MINH CHỨNG THÀNH TÍCH.docx
A39: 34 | B39: Trần Thị Ánh Lan | C39: 3122540040 | D39: VĂN HOÁ VÀ DU LỊCH | E39: =VLOOKUP(C39,'Trang tính3'!$B$10:$H$377,7,0) -> 100 | F39: =VLOOKUP(C39,'Trang tính2'!$B$1:$D$175,3,0) -> 3.18 | J39: MC không có xác nhận | L39: MC không có xác nhận | N39: KHÔNG ĐẠT | O39: TRẦN THỊ ÁNH LAN - 3122540040 - VHDL - BẢNG KHAI THÀNH TÍCH CÁ NHÂN.docx | P39: TRẦN THỊ ÁNH LAN - 3122540040 - VHDL - MINH CHỨNG THÀNH TÍCH CÁ NHÂN.docx
A40: 35 | B40: Trần Thị Thùy Duyên | C40: 3123540014 | D40: VĂN HOÁ VÀ DU LỊCH | E40: =VLOOKUP(C40,'Trang tính3'!$B$10:$H$377,7,0) -> 95.5 | F40: =VLOOKUP(C40,'Trang tính2'!$B$1:$D$175,3,0) -> 3.66 | H40: Giấy chứng nhận do Khoa Văn hóa và Du lịch cấp về việc Đã tham gia và hoàn thành tốt Minigame Tìm hiểu Luật biển Việt Nam Cuộc thi trắc nghiệm tương tác trực tuyến tìm hiểu về 80 năm Ngày Tổng tuyển cử đầu tiên bầu Quốc hội Việt Nam (06/01/1946 – 06/01/2026) | I40: Giấy chứng nhận của trường Đại học Sài Gòn theo Quyết định số 157/GCN-ĐHSG ngày 15/05/2025 về việc Thực hiện hoàn thành đề tài nghiên cứu khoa học cấp trường Giấy khen của Hiệu trưởng trường Đại học Sài Gòn theo Quyết định số 1223/QĐ-DHSG ngày 14/05/2025 về việc Đạt giải Khuyến khích lĩnh vực khoa học Xã hội và Nhân văn Cuộc thi Sinh viên nghiên cứu khoa học cấp trường năm 2025 | J40: Chứng nhận của Ban thư ký Hội sinh viên trường Đại học Sài Gòn theo Quyết định số 02/GCN-BTK ngày 18/08/2025 về việc Đã tham gia Hội thao Chào mừng Đại hội đại biểu Hội sinh viên Việt Nam trường Đại học Sài Gòn lần thứ IX, nhiệm kỳ 2025 - 2028 do Liên Chi hội sinh viên các khoa: Văn hóa và Du lịch, Ngoại ngữ, Khoa học Xã hội và Nghệ thuật , Luật đồng tổ chức. Đạt Danh hiệu “Sinh viên khỏe” trường Đại học Sài Gòn năm học 2024 – 2025 Giải nhất Kéo co Hội thao chào mừng Đại hội đại biểu Hội sinh viên trường Đại học Sài Gòn lần thứ IX, nhiệm kỳ 2025 – 2028 do Liên chi hội sinh viên các khoa: Văn hóa và Du lịch, Ngoại ngữ, Khoa học xã hội và Nghệ thuật, Luật đồng tổ chức | K40: Giấy chứng nhận của Câu lạc bộ Vòng tay lớn TP.Hồ Chí Minh theo quyết định số 021-GCN/VTL-MHX ngày 27/07/2025 về việc Là chiến sĩ chiến dịch thanh niên tình nguyện hè “Mùa hè xanh” năm 2025 tại phường Long An, tỉnh Tây Ninh Thời gian: 9 ngày (Từ 19/07/2025 đến 27/07/2025) Tiếp sức mùa thi kỳ thi Đánh giá năng lực năm 2025 Cụm thi trường Đại học Sài Gòn Thời gian: 1 ngày, ngày 01/06/2025 | L40: Chứng chỉ Aptis Esol trình độ B1, cấp ngày 23/11/2025. Đơn vị cấp: British Council Chứng nhận của Trung tâm hỗ trợ học sinh, sinh viên TP.Hồ Chí Minh theo Quyết định số 04.25/GCN-HTHSSV ngày 28/08/2025 về việc Hoàn thành lớp kỹ năng Tư duy sáng tạo Giấy chứng nhận của Câu lạc bộ Republic of English về việc Đã hoàn thành buổi workshop Take it out - Chinh phục kỹ năng nói | N40: ĐẠT | O40: TRẦN THỊ THÙY DUYÊN - 3123540014 - KHOA VĂN HÓA VÀ DU LỊCH - BẢNG KHAI THÀNH TÍCH (1) (2).docx | P40: TRẦN THỊ THÙY DUYÊN - 3123540014 - KHOA VĂN HÓA VÀ DU LỊCH - MINH CHỨNG THÀNH TÍCH (3).docx
A41: 36 | B41: Nguyễn Thị Thiện Nhàn | C41: 3121540085 | D41: VĂN HOÁ VÀ DU LỊCH | E41: 99 | F41: 3.87 | H41: Kết quả đánh giá chất lượng Đoàn viên năm học 2024 - 2025 đạt Hoàn thành xuất sắc nhiệm vụ. Là thành viên chính thức đội thi tham gia Hội thi Olympic các môn khoa học Mác – Lênin, tư tưởng Hồ Chí Minh năm 2025 do Trường Đại học Sài Gòn tổ chức. Là Đảng viên dự bị từ ngày 05/10/2024. | I41: Thực hiện đề tài khóa luận tốt nghiệp: “Quá trình điều chỉnh chính sách đối ngoại của Hoa Kỳ đối với khu vực Đông Nam Á trong hai thập niên đầu của thế kỷ XIX (2000-2020)” đạt 9.2 điểm, loại Xuất sắc. | J41: Đạt danh hiệu “Thanh niên khỏe” trường Đại học Sài Gòn năm 2024 theo Giấy chứng nhận số 02 - QĐGCN/HSV ngày 05/10/2024. | K41: Nhận Giấy khen của Trường Đại học Sài Gòn vì đã có thành tích xuất sắc trong Chiến dịch Xuân Tình nguyện lần thứ 17 năm 2025. Tham gia và nhận giấy chứng nhận hoàn thành Chiến dịch Xuân Tình nguyện trường Đại học Sài Gòn lần thứ 17 năm 2025. Tham gia chương trình “Vui Hội Trăng Rằm” năm 2024 tương ứng 01 ngày tình nguyện. Tham gia chương trình “Xuân san sẻ - Tết yêu thương” tương ứng 01 ngày tình nguyện. Tham gia chương trình “Tô vẽ mảng tường” tương ứng 01 ngày tình nguyện. Tham gia chương trình “Ngày Chủ nhật xanh lần thứ 156 năm 2025” và “Ngày Thứ bảy tình nguyện năm 2025”. | L41: Đạt trình độ ngoại ngữ tiếng Anh Aptis ESOL trình độ B1. Tham gia Chương trình Giao lưu và tặng quà cho sinh viên Lào tại ký túc xá sinh viên Lào Thành phố Hồ Chí Minh năm 2025. Xuất sắc hoàn thành nhiệm vụ tại khu vực “ASEAN Explorer - Sinh viên Đại học Sài Gòn tự tin hội nhập” trong Ngày hội Tân Sinh viên SGU's Day 2024. Nhận Giấy khen của Hội sinh viên Trường Đại học Sài Gòn vì có thành tích xuất sắc trong công tác Hội và phong trào sinh viên khoa Văn hoá và Du lịch nhiệm kỳ 2023-2025. Hoàn thành lớp tập huấn chuyên đề “Ứng dụng kỹ năng số cho sinh viên năm 2024” và chuyên đề “An toàn giao thông và kỹ năng phòng tránh va chạm trong hoạt động tình nguyện”. | M41: Đề xuất tiêu biểu | N41: ĐẠT | O41: 32.NGUYỄN THIỆN NHÀN .docx | P41: 32. NGUYỄN THỊ THIỆN NHÀN
...

